Workbook

Sheet 1. Financial Structure Analysis
B1: Shell 2024 and 2023
B3: Abbreviations | E3: Name: THI MINH THUAN PHUNG Student number: 20115516
B4: Statement of Financial Position (Balance Sheet) | C4: SFP
B5: Income Statement | C5: I/S
B6: Statement of cashflow | C6: SCF
B8: All $ figures in millions unless specifed otherwise | C8: Million $
B10: Financial Structure Analysis
A12: W1 | B12: Liabilities/Debt
C13: 2024 | D13: 2023 | F13: Page 242
B14: Current Debt | C14: 11630 | D14: 9931 | F14: SFP
B15: Non-current Debt (long term) | C15: 65448 | D15: 71610 | F15: SFP
B16: Total Debt | C16: =SUM(C14:C15) -> 77078 | D16: =SUM(D14:D15) -> 81541
B17: Cash and cash equivalents | C17: 39110 | D17: 38774 | F17: SPF, Note 21 debt, page 286
B18: Net Debt | C18: =C16-C17 +841 -> 38809 | D18: =D16-D17 +775 -> 43542
B20: Equity | C20: 180168 | D20: 188362 | F20: SFP
B22: Total Finance Capital | C22: =C18+C20 -> 218977 | D22: =D18+D20 -> 231904
B24: Gearing | C24: =C18/C22 -> 0.17722866 | D24: =D18/D22 -> 0.18775873
A28: W2 | B28: Maturity Profile of Debt | C28: 2024 | D28: 2023 | E28: 2024 | F28: 2023 | G28: Note 21, Page 285
E29: % of Borrowings
B30: Under 1 year | C30: 6921 | D30: 5352 | E30: =C30/$C$38 -> 0.22726079 | F30: =D30/$D$38 -> 0.15583508
B31: 1 to 2 years | C31: 3961 | D31: 6424 | E31: =C31/$C$38 -> 0.13006502 | F31: =D31/$D$38 -> 0.18704868
B32: 2 to 3 years | C32: 2413 | D32: 3929 | E32: =C32/$C$38 -> 0.079234255 | F32: =D32/$D$38 -> 0.11440135
B33: 3 to 4 years | C33: 5496 | D33: 2835 | E33: =C33/$C$38 -> 0.1804689 | F33: =D33/$D$38 -> 0.08254717
B34: 4 to 5 years | C34: 2365 | D34: 5495 | E34: =C34/$C$38 -> 0.077658107 | F34: =D34/$D$38 -> 0.15999884
B35: Over 5 | C35: 27615 | D35: 30365 | E35: =C35/$C$38 -> 0.90677743 | F35: =D35/$D$38 -> 0.88414279
B36: Total Repayments | C36: =SUM(C30:C35) -> 48771 | D36: =SUM(D30:D35) -> 54400
B37: Interest | C37: -18317 | D37: -20056
B38: Total Debt | C38: =SUM(C36:C37) -> 30454 | D38: =SUM(D36:D37) -> 34344
A42: W3 | B42: Other workings
B43: Fixed versus variable | C43: 2024 | D43: 2023
B44: Fixed Debt | C44: Notdisclosed | D44: Notdisclosed
B45: Variable Debt | C45: Notdisclosed | D45: Notdisclosed
C46: Most debt is raised from central borrowing programmes. Shell's policy is to have debt principally denominated in dollars and to retain a balanced exposure to fixed and floating rates over time. Shell has issued a significant amount of fixed rate debt in recent years, taking advantage of historically low interest rates. As a result, the majority of the debt portfolio at December 31, 2024, is fixed | F46: Note 26, Page 299
A50: W4 | B50: Currency Profile of Debt | C50: 2024 | D50: 2023
B51: GBP | C51: Notdisclosed | D51: Notdisclosed | F51: Page 141
B52: EUR | C52: Notdisclosed | D52: Notdisclosed | F52: Note 26 page 301
B53: Other
A58: W5 | B58: Sensitivity of Rates | C58: 2024 | D58: 2023
B59: Movement in rates | C59: =-69+98+34-103+30 -> -10 | D59: =-270-46+49-129+9 -> -387 | F59: Note 26, Page 302
B60: Movement in exchange rates (proxy; sum of 10% appreciation vs USD across listed currencies)
...

Sheet 1. AR Screenshot
A1: 1. Financial Structure Analysis Screenshot

Sheet 2. Assest and Operational Analy
B1: Shell 2024 and 2023
B3: Abbreviations | E3: Source is noted where applicable
B4: Statement of Financial Position (Balance Sheet) | C4: SFP
B5: Income Statement | C5: I/S
B6: Statement of cashflow | C6: SCF
B12: ASSET PERFORMANCE ANALYSIS
A14: W15 | B14: Non-Current Assets Base - Growth Rate
D15: 2024 | F15: 2023 | H15: 2022 | I15: page 244
B16: Total Non Current Assets | D16: 259683 | F16: 272155 | H16: 277086 | I16: SFP
B17: Growth Rate | D17: =D16/F16-1 -> -0.045826827 | F17: =F16/H16-1 -> -0.017795919
A21: W16 | B21: Strength of Balance Sheet - % Intangibles | D21: 2024 | F21: 2023 | I21: page 244
B22: Intangible Assets | D22: 9480 | E22: =D22/D23 -> 0.036506048 | F22: 10253 | G22: =F22/F23 -> 0.037673385 | I22: SFP
B23: Total Non-Current Assets | D23: 259683 | F23: 272155 | I23: SFP
B25: Goodwill | D25: 16032 | E25: =D25/D26 -> 0.06173681 | F25: 16660 | G25: =F25/F26 -> 0.061215116 | I25: SFP
B26: Total Non-Current Assets | D26: 259683 | F26: 272155 | I26: SFP
A30: W17 | B30: Asset Performance - Profit Based Measures
B31: RoA | D31: 2024 | F31: 2023
B32: Earnings Before Interest and Tax (operating profit) | D32: =(29922 +4787) -> 34709 | E32: =D32/D33 -> 0.089546424 | F32: =(32627+4673) -> 37300 | G32: =F32/F33 -> 0.091810865 | I32: I/S | Q32: Earnings Before Interest and Tax = Income before taxation + interest expense
B33: Total Assets | D33: 387609 | F33: 406270 | I33: SFP
B35: Return on Non-Current Assets | D35: =D3 -> 0
B36: Earnings Before Interest and Tax | D36: =D32 -> 34709 | E36: =D36/D37 -> 0.13365912 | F36: =F32 -> 37300 | G36: =F36/F37 -> 0.13705425 | I36: I/S
B37: Total Non-Current Assets | D37: 259683 | F37: 272155 | I37: SFP
B39: ROCE
B40: Earnings Before Interest and Tax | D40: =D32 -> 34709 | E40: =D40/D41 -> 0.11616987 | F40: =F32 -> 37300 | G40: =F40/F41 -> 0.11989329 | I40: I/S
B41: Total Assets - Current Liabilities | D41: =D33-88831 -> 298778 | F41: =F33-95160 -> 311110 | I41: SFP
B43: ROCE version 2
B44: Earnings Before Interest and Tax - Non-recurring items | D44: =D32-47 -> 34662 | E44: =D44/D45 -> 0.11601256 | F44: =F32-(-201) -> 37501 | G44: =F44/F45 -> 0.12053936 | I44: I/S
B45: Total Assets - Current Liabilities | D45: =D41 -> 298778 | F45: =F41 -> 311110 | I45: SFP
A49: W18 | B49: Asset Performance - Revenue Based Measures | D49: 2024 | F49: 2023
B50: Asset Turnover
B51: Revenue | D51: 284312 | E51: =D51/D52 -> 0.73350206 | F51: 316620 | G51: =F51/F52 -> 0.77933394 | I51: I/S
B52: Total Assets | D52: =D33 -> 387609 | F52: =F33 -> 406270 | I52: SFP
A56: W19 | B56: Asset Performance - Employee Based Measures | D56: 2024 | F56: 2023
B57: Revenue per Employee
B58: Revenue | D58: =D51 -> 284312 | E58: =(D58/D59)*1000000 -> 2961583.3 | F58: =F51 -> 316620 | G58: =(F58/F59)*1000000 -> 3073980.6 | I58: I/S
B59: Total No of Employees | D59: 96000 | F59: 103000 | I59: page 117
B61: Average cost per employee
B62: Total Wages | D62: 10928 | E62: =D62/D63 * 1000000 -> 113833.33 | F62: 10648 | G62: =F62/F63 * 1000000 -> 103378.64 | I62: Note 33, page 313
B63: Total No of Employees | D63: 96000 | F63: 103000
B67: OPERATIONAL ANALYSIS
...

Sheet 2. AR Screenshot
A2: 2. Assest and Operational Analysis screenshot

Sheet 3. Cash flow analysis
B1: Shell 2024 and 2023
B3: Abbreviations | F3: Source is noted where applicable
B4: Statement of Financial Position (Balance Sheet) | D4: SFP
B5: Income Statement | D5: I/S
B6: Statement of cashflow | D6: SCF
B8: All $ figures in millions unless specifed otherwise
B12: CASH FLOW ANALYSIS
A14: W27 | B14: Headline Analysis - | D14: 2024 | F14: 2023
B15: Cash Inflow from Operations | D15: 54687 | F15: 54191 | J15: SCF
B16: Cash Inflow / (Outflow) from Investing Activities | D16: -15155 | F16: -17734 | J16: SCF
B17: Cash (Outflow) from Financing Activities | D17: -38435 | F17: -38235 | J17: SCF
B18: Net Cash Movement | D18: =SUM(D15:D17) -> 1097 | F18: =SUM(F15:F17) -> -1778
B22: Cash Flow from Operating Activties
A24: W28 | B24: Net Cash Flow From Operations | D24: 2024 | F24: 2023 | H24: 2022
B25: Net Cash Flow From Operations | D25: =D15 -> 54687 | F25: =F15 -> 54191 | H25: 68414 | J25: SCF
B26: Change % | D26: =D25/F25-1 -> 0.0091528114 | F26: =F25/H25-1 -> -0.20789604
B28: Net Cash Flow From Operations | D28: =D15 -> 54687 | F28: =F15 -> 54191 | J28: SCF
B29: Operating Profit / (Loss) | D29: ='2. Assest and Operational Analy'!D71 -> 34709 | F29: ='2. Assest and Operational Analy'!F71 -> 37300 | J29: I/S
B30: Cash Flow great than profits | D30: Yes | F30: Yes | H30: Yes
A34: W29 | B34: Operating Cash Margin | D34: 2024 | F34: 2023
B35: Operating Cash Flow | D35: =D15 -> 54687 | E35: =D35/D36 -> 0.19234855 | F35: =F15 -> 54191 | G35: =F35/F36 -> 0.1711547 | J35: SCF
B36: Revenue | D36: ='2. Assest and Operational Analy'!D89 -> 284312 | F36: ='2. Assest and Operational Analy'!F89 -> 316620 | J36: I/S
A40: W30 | B40: Net Debt to Cash Flow | D40: 2024 | F40: 2023
B41: Net Debt | D41: ='1. Financial Structure Analysis'!C18 -> 38809 | E41: =D41/D42 -> 0.70965677 | F41: ='1. Financial Structure Analysis'!D18 -> 43542 | G41: =F41/F42 -> 0.80349135 | J41: Page 244
B42: Operating Cashflow | D42: =D15 -> 54687 | E42: Years | F42: =F15 -> 54191 | G42: Years | J42: SCF
B44: Interest Servicing Ability | D44: 2024 | F44: 2023
B45: Interest Paid | D45: 4557 | E45: =D45/D46 -> 0.083328762 | F45: 4441 | G45: =F45/F46 -> 0.081950877
B46: Operating Cash Flow | D46: =D15 -> 54687 | F46: =F15 -> 54191 | J46: SCF
B48: Interest Rate - estimate | D48: 2024 | F48: 2023
B49: Interest Paid | D49: =D45 -> 4557 | E49: =D49/D50 -> 0.059121928 | F49: =F45 -> 4441 | G49: =F49/F50 -> 0.054463399
B50: Total Debt | D50: ='1. Financial Structure Analysis'!C16 -> 77078 | F50: ='1. Financial Structure Analysis'!D16 -> 81541
B54: Cash Flow from Investing Activties
A56: W31 | B56: Replacement Rate | D56: 2024 | F56: 2023
B57: PPE | D57: 185219 | F57: 194835 | H57: SFP | I57: Page 242
B58: Intangibles | D58: 9480 | F58: 10253 | H58: SFP | I58: Note 12 page 275
D59: =SUM(D57:D58) -> 194699 | F59: =SUM(F57:F58) -> 205088
B61: Additions to PPE | D61: 26446 | F61: 25831 | H61: Note 12, Page 383 | I61: Page 383
B62: Additions to Intangibles | D62: 4456 | F62: 5558 | H62: Note 12, Page 383
D63: =SUM(D61:D62) -> 30902 | F63: =SUM(F61:F62) -> 31389
B65: Replacement Rate (notional years) | D65: =D59/D63 -> 6.3005307 | F65: =F59/F63 -> 6.5337539
...

Sheet 3.AR Screenshot
A2: 3. Cash flow analysis screenshot

Sheet 4. CFA Valuation
B1: Shell 2024 and 2023
B3: Abbreviations | F3: Source is noted where applicable
B4: Statement of Financial Position | C4: SFP
B5: Income Statement | C5: I/S
B6: Statement of cashflow | C6: SCF
B11: VALUATION
G12: Rate 2024: GBP/USD : 1.2781 Rate 2023: GBP/USD : 1.2439
A13: W36 | B13: Market Capitalisation | C13: 2024 | E13: 2023
B15: Share price USD | C15: ='1. Financial Structure Analysis'!C155/100 *1.2781 -> 31.645756 | E15: ='1. Financial Structure Analysis'!D155/100*1.2439 -> 31.955791 | G15: W13 Finance Structure analysis
B16: No. of Shares | C16: 6115031158 | E16: 6524109049 | G16: 27. Share capital, Page 307
B17: Market Capitalisation (millions) USD | C17: =C16*C15/1000000 -> 193514.78 | E17: =E16*E15/1000000 -> 208483.07
B18: Market cap growth | C18: =(C17-E17)/E17 -> -0.071796149
A22: W37 | B22: Enterprise Value(EV)
C23: 2024 | E23: 2023
B24: Equity Value | C24: 180168 | E24: 188362 | G24: W1 Financial Structure analysis
B25: Net Debt Value | C25: 38809 | E25: 43542 | G25: W1 Financial Structure analysis
B26: Enterprise Value | C26: =SUM(C24:C25) -> 218977 | E26: =SUM(E24:E25) -> 231904
A30: W38 | B30: Cash-based Valuation
C31: 2024 | E31: 2023
B32: FCF | C32: ='3. Cash flow analysis'!D126 -> 39532 | E32: ='3. Cash flow analysis'!F126 -> 36457
B33: FCF yield | C33: ='3. Cash flow analysis'!E130 -> 0.1633628 | E33: ='3. Cash flow analysis'!G130 -> 0.13359987
B34: EV/FCF | C34: =C26/C32 -> 5.539234 | E34: =E26/E32 -> 6.3610281
B35: Dividend yield | C35: ='3. Cash flow analysis'!D107/C17 -> 0.044792443 | E35: ='3. Cash flow analysis'!F107/E17 -> 0.040257466
B36: Payout | C36: ='3. Cash flow analysis'!D107/C32 -> 0.21926541 | E36: ='3. Cash flow analysis'!F107/E32 -> 0.23021642
B37: Adjusted EBITDA | C37: 65803 | E37: 68538
B38: EV/EBITDA | C38: =C26/C37 -> 3.3277662 | E38: =E26/E37 -> 3.3835828
B39: Implied EV (at 2023 multiple) | C39: =C37*E38 -> 222649.9

Sheet 4.AR Screenshot
A2: 4. CFA Valuation screenshot
